2024-03-09 18:48:52,492 INFO    StreamThr :18354 [internal.py:wandb_internal():86] W&B internal server running at pid: 18354, started at: 2024-03-09 18:48:52.492308
2024-03-09 18:48:52,494 DEBUG   HandlerThread:18354 [handler.py:handle_request():146] handle_request: status
2024-03-09 18:48:52,501 INFO    WriterThread:18354 [datastore.py:open_for_write():85] open: /home/yuezk/yzk/ViTac/ManiSkill-ViTac2024/wandb/run-20240309_184852-rrqdx8ym/run-rrqdx8ym.wandb
2024-03-09 18:48:52,501 DEBUG   SenderThread:18354 [sender.py:send():380] send: header
2024-03-09 18:48:52,506 DEBUG   SenderThread:18354 [sender.py:send():380] send: run
2024-03-09 18:48:53,017 DEBUG   HandlerThread:18354 [handler.py:handle_request():146] handle_request: shutdown
2024-03-09 18:48:53,017 INFO    HandlerThread:18354 [handler.py:finish():866] shutting down handler
2024-03-09 18:48:53,506 INFO    WriterThread:18354 [datastore.py:close():294] close: /home/yuezk/yzk/ViTac/ManiSkill-ViTac2024/wandb/run-20240309_184852-rrqdx8ym/run-rrqdx8ym.wandb
2024-03-09 18:49:57,091 INFO    SenderThread:18354 [retry.py:__call__():172] Retry attempt failed:
Traceback (most recent call last):
  File "/home/yuezk/anaconda3/envs/mani_vitac/lib/python3.10/site-packages/urllib3/connectionpool.py", line 467, in _make_request
    six.raise_from(e, None)
  File "<string>", line 3, in raise_from
  File "/home/yuezk/anaconda3/envs/mani_vitac/lib/python3.10/site-packages/urllib3/connectionpool.py", line 462, in _make_request
    httplib_response = conn.getresponse()
  File "/home/yuezk/anaconda3/envs/mani_vitac/lib/python3.10/http/client.py", line 1368, in getresponse
    response.begin()
  File "/home/yuezk/anaconda3/envs/mani_vitac/lib/python3.10/http/client.py", line 317, in begin
    version, status, reason = self._read_status()
  File "/home/yuezk/anaconda3/envs/mani_vitac/lib/python3.10/http/client.py", line 278, in _read_status
    line = str(self.fp.readline(_MAXLINE + 1), "iso-8859-1")
  File "/home/yuezk/anaconda3/envs/mani_vitac/lib/python3.10/socket.py", line 705, in readinto
    return self._sock.recv_into(b)
  File "/home/yuezk/anaconda3/envs/mani_vitac/lib/python3.10/ssl.py", line 1273, in recv_into
    return self.read(nbytes, buffer)
  File "/home/yuezk/anaconda3/envs/mani_vitac/lib/python3.10/ssl.py", line 1129, in read
    return self._sslobj.read(len, buffer)
TimeoutError: The read operation timed out

During handling of the above exception, another exception occurred:

Traceback (most recent call last):
  File "/home/yuezk/anaconda3/envs/mani_vitac/lib/python3.10/site-packages/requests/adapters.py", line 486, in send
    resp = conn.urlopen(
  File "/home/yuezk/anaconda3/envs/mani_vitac/lib/python3.10/site-packages/urllib3/connectionpool.py", line 799, in urlopen
    retries = retries.increment(
  File "/home/yuezk/anaconda3/envs/mani_vitac/lib/python3.10/site-packages/urllib3/util/retry.py", line 550, in increment
    raise six.reraise(type(error), error, _stacktrace)
  File "/home/yuezk/anaconda3/envs/mani_vitac/lib/python3.10/site-packages/urllib3/packages/six.py", line 770, in reraise
    raise value
  File "/home/yuezk/anaconda3/envs/mani_vitac/lib/python3.10/site-packages/urllib3/connectionpool.py", line 715, in urlopen
    httplib_response = self._make_request(
  File "/home/yuezk/anaconda3/envs/mani_vitac/lib/python3.10/site-packages/urllib3/connectionpool.py", line 469, in _make_request
    self._raise_timeout(err=e, url=url, timeout_value=read_timeout)
  File "/home/yuezk/anaconda3/envs/mani_vitac/lib/python3.10/site-packages/urllib3/connectionpool.py", line 358, in _raise_timeout
    raise ReadTimeoutError(
urllib3.exceptions.ReadTimeoutError: HTTPSConnectionPool(host='api.wandb.ai', port=443): Read timed out. (read timeout=20)

During handling of the above exception, another exception occurred:

Traceback (most recent call last):
  File "/home/yuezk/anaconda3/envs/mani_vitac/lib/python3.10/site-packages/wandb/sdk/lib/retry.py", line 131, in __call__
    result = self._call_fn(*args, **kwargs)
  File "/home/yuezk/anaconda3/envs/mani_vitac/lib/python3.10/site-packages/wandb/sdk/internal/internal_api.py", line 366, in execute
    return self.client.execute(*args, **kwargs)  # type: ignore
  File "/home/yuezk/anaconda3/envs/mani_vitac/lib/python3.10/site-packages/wandb/vendor/gql-0.2.0/wandb_gql/client.py", line 52, in execute
    result = self._get_result(document, *args, **kwargs)
  File "/home/yuezk/anaconda3/envs/mani_vitac/lib/python3.10/site-packages/wandb/vendor/gql-0.2.0/wandb_gql/client.py", line 60, in _get_result
    return self.transport.execute(document, *args, **kwargs)
  File "/home/yuezk/anaconda3/envs/mani_vitac/lib/python3.10/site-packages/wandb/sdk/lib/gql_request.py", line 58, in execute
    request = self.session.post(self.url, **post_args)
  File "/home/yuezk/anaconda3/envs/mani_vitac/lib/python3.10/site-packages/requests/sessions.py", line 637, in post
    return self.request("POST", url, data=data, json=json, **kwargs)
  File "/home/yuezk/anaconda3/envs/mani_vitac/lib/python3.10/site-packages/requests/sessions.py", line 589, in request
    resp = self.send(prep, **send_kwargs)
  File "/home/yuezk/anaconda3/envs/mani_vitac/lib/python3.10/site-packages/requests/sessions.py", line 703, in send
    r = adapter.send(request, **kwargs)
  File "/home/yuezk/anaconda3/envs/mani_vitac/lib/python3.10/site-packages/requests/adapters.py", line 532, in send
    raise ReadTimeout(e, request=request)
requests.exceptions.ReadTimeout: HTTPSConnectionPool(host='api.wandb.ai', port=443): Read timed out. (read timeout=20)
2024-03-09 19:01:21,334 INFO    SenderThread:18354 [dir_watcher.py:__init__():211] watching files in: /home/yuezk/yzk/ViTac/ManiSkill-ViTac2024/wandb/run-20240309_184852-rrqdx8ym/files
2024-03-09 19:01:21,335 INFO    SenderThread:18354 [sender.py:_start_run_threads():1124] run started: rrqdx8ym with start time 1709981332.499627
2024-03-09 19:01:21,335 INFO    SenderThread:18354 [sender.py:finish():1536] shutting down sender
2024-03-09 19:01:21,335 INFO    SenderThread:18354 [dir_watcher.py:finish():358] shutting down directory watcher
2024-03-09 19:01:22,335 INFO    SenderThread:18354 [dir_watcher.py:finish():388] scan: /home/yuezk/yzk/ViTac/ManiSkill-ViTac2024/wandb/run-20240309_184852-rrqdx8ym/files
2024-03-09 19:01:22,336 INFO    SenderThread:18354 [dir_watcher.py:finish():402] scan save: /home/yuezk/yzk/ViTac/ManiSkill-ViTac2024/wandb/run-20240309_184852-rrqdx8ym/files/config.yaml config.yaml
2024-03-09 19:01:22,336 INFO    SenderThread:18354 [file_pusher.py:finish():175] shutting down file pusher
2024-03-09 19:01:22,336 INFO    SenderThread:18354 [file_pusher.py:join():181] waiting for file pusher
2024-03-09 19:01:24,455 INFO    wandb-upload_0:18354 [upload_job.py:push():131] Uploaded file /home/yuezk/yzk/ViTac/ManiSkill-ViTac2024/wandb/run-20240309_184852-rrqdx8ym/files/config.yaml
2024-03-09 19:01:24,840 INFO    SenderThread:18354 [file_stream.py:finish():595] file stream finish called
2024-03-09 19:01:25,331 INFO    SenderThread:18354 [file_stream.py:finish():599] file stream finish is done
