2024-03-12 00:17:13,907 INFO    MainThread:34347 [wandb_setup.py:_flush():76] Current SDK version is 0.16.0
2024-03-12 00:17:13,908 INFO    MainThread:34347 [wandb_setup.py:_flush():76] Configure stats pid to 34347
2024-03-12 00:17:13,908 INFO    MainThread:34347 [wandb_setup.py:_flush():76] Loading settings from /home/yuezk/.config/wandb/settings
2024-03-12 00:17:13,908 INFO    MainThread:34347 [wandb_setup.py:_flush():76] Loading settings from /home/yuezk/yzk/ViTac/ManiSkill-ViTac2024/wandb/settings
2024-03-12 00:17:13,908 INFO    MainThread:34347 [wandb_setup.py:_flush():76] Loading settings from environment variables: {}
2024-03-12 00:17:13,908 INFO    MainThread:34347 [wandb_setup.py:_flush():76] Applying setup settings: {'_disable_service': False}
2024-03-12 00:17:13,908 INFO    MainThread:34347 [wandb_setup.py:_flush():76] Inferring run settings from compute environment: {'program_relpath': 'scripts/universal_training_script.py', 'program_abspath': '/home/yuezk/yzk/ViTac/ManiSkill-ViTac2024/scripts/universal_training_script.py', 'program': '/home/yuezk/yzk/ViTac/ManiSkill-ViTac2024/scripts/universal_training_script.py'}
2024-03-12 00:17:13,908 INFO    MainThread:34347 [wandb_init.py:_log_setup():524] Logging user logs to /home/yuezk/yzk/ViTac/ManiSkill-ViTac2024/wandb/run-20240312_001713-jxpp1po4/logs/debug.log
2024-03-12 00:17:13,908 INFO    MainThread:34347 [wandb_init.py:_log_setup():525] Logging internal logs to /home/yuezk/yzk/ViTac/ManiSkill-ViTac2024/wandb/run-20240312_001713-jxpp1po4/logs/debug-internal.log
2024-03-12 00:17:13,908 INFO    MainThread:34347 [wandb_init.py:init():564] calling init triggers
2024-03-12 00:17:13,909 INFO    MainThread:34347 [wandb_init.py:init():571] wandb.init called with sweep_config: {}
config: {'env': {'max_action': array([4., 2., 2.]), 'step_penalty': 1, 'final_reward': 10, 'max_steps': 100, 'sensor_offset_x_range_len': 2.0, 'sensor_offset_z_range_len': 2.0, 'key_x_max_offset': 10, 'key_y_max_offset': 0, 'key_z_max_offset': 0, 'normalize': False, 'marker_random_noise': 0.5, 'marker_lose_tracking_probability': 0.01, 'marker_interval_range': [1.95, 2.15], 'marker_rotation_range': 0.1, 'marker_translation_range': [1, 1], 'marker_pos_shift_range': [0.1, 0.1]}, 'policy': {'buffer_size': 200000, 'train_freq': 2, 'gradient_steps': -1, 'learning_starts': 2000, 'target_policy_noise': 0.5, 'target_noise_clip': 1, 'action_noise': VecNoise(BaseNoise=NormalActionNoise(mu=[0 0 0], sigma=[0.5 0.5 0.5])), n_envs=1), 'batch_size': 128, 'learning_rate': 0.0003, 'policy_delay': 2, 'policy_kwargs': {'net_arch': {'pi': [256, 256], 'qf': [256, 256]}, 'pointnet_in_dim': 4, 'pointnet_out_dim': 32, 'pointnet_batchnorm': False, 'pointnet_layernorm': True, 'zero_init_output': True, 'use_relative_motion': True}, 'device': 'cuda:0', 'seed': 0, 'tensorboard_log': '/home/yuezk/yzk/ViTac/ManiSkill-ViTac2024/scripts/../training_log/long_open_lock_2024-03-12_00-17-04.977'}, 'train': {'algorithm_name': 'TD3', 'total_timesteps': 100000, 'log_interval': 10, 'checkpoint_every': 2000, 'eval_freq': 2000, 'n_eval': 50, 'parallel': 1, 'seed': 0, 'device': 'cuda:0', 'gpu': 0, 'name': 'long_open_lock', 'wandb_name': 'ManiSkill_ViTac', 'emp': {}}, 'cfg': 'configs/parameters/long_open_lock.yaml', 'no_render': False}
2024-03-12 00:17:13,909 INFO    MainThread:34347 [wandb_init.py:init():614] starting backend
2024-03-12 00:17:13,909 INFO    MainThread:34347 [wandb_init.py:init():618] setting up manager
2024-03-12 00:17:13,913 INFO    MainThread:34347 [backend.py:_multiprocessing_setup():105] multiprocessing start_methods=fork,spawn,forkserver, using: spawn
2024-03-12 00:17:13,914 INFO    MainThread:34347 [wandb_init.py:init():624] backend started and connected
2024-03-12 00:17:14,000 INFO    MainThread:34347 [wandb_init.py:init():716] updated telemetry
2024-03-12 00:17:14,003 INFO    MainThread:34347 [wandb_init.py:init():749] communicating run to backend with 90.0 second timeout
2024-03-12 00:17:15,433 ERROR   MainThread:34347 [wandb_init.py:init():775] encountered error: It appears that you do not have permission to access the requested resource. Please reach out to the project owner to grant you access. If you have the correct permissions, verify that there are no issues with your networking setup.(Error 403: Forbidden)
2024-03-12 00:17:16,143 ERROR   MainThread:34347 [wandb_init.py:init():1184] It appears that you do not have permission to access the requested resource. Please reach out to the project owner to grant you access. If you have the correct permissions, verify that there are no issues with your networking setup.(Error 403: Forbidden)
Traceback (most recent call last):
  File "/home/yuezk/anaconda3/envs/mani_vitac/lib/python3.10/site-packages/wandb/sdk/wandb_init.py", line 1166, in init
    run = wi.init()
  File "/home/yuezk/anaconda3/envs/mani_vitac/lib/python3.10/site-packages/wandb/sdk/wandb_init.py", line 781, in init
    raise error
wandb.errors.CommError: It appears that you do not have permission to access the requested resource. Please reach out to the project owner to grant you access. If you have the correct permissions, verify that there are no issues with your networking setup.(Error 403: Forbidden)
2024-03-12 00:17:17,146 WARNING MsgRouterThr:34347 [router.py:message_loop():77] message_loop has been closed
